Workbook

Sheet NiCOlit
B1: substrate | C1: eq_substrate | D1: effective_coupling_partner | E1: eq_coupling_partner | F1: pre_catalyst | G1: eq_catalyst | H1: solvent | I1: effective_reagents | J1: eq_reagent | K1: effective_ligand | L1: eq_ligand | M1: temperature | N1: time | O1: product | P1: doi | Q1: yield
A2: 0 | B2: COc1ccc2ccccc2c1 | C2: 1 | D2: [Li]c1ccccc1 | E2: 1.5 | F2: C1CC=CCCC=C1->[Ni]<-C2=CCCC=CCC2 | G2: 0.05 | H2: c1ccccc1C | I2: blank_cell | J2: 0 | K2: blank_cell | L2: 0 | M2: 25 | N2: 12 | O2: c3ccc(c2ccc1ccccc1c2)cc3 | P2: =VLOOKUP(A2,all_NiCOlit!A:B,2,TRUE) -> https://doi.org/10.1002/chem.201603436 | Q2: 73
A3: 1 | B3: COc1ccc2ccccc2c1 | C3: 1 | D3: [Li]c1ccccc1 | E3: 1.5 | F3: C1CC=CCCC=C1->[Ni]<-C2=CCCC=CCC2 | G3: 0.05 | H3: c1ccccc1C | I3: blank_cell | J3: 0 | K3: C1CCC(P(C2CCCCC2)C2CCCCC2)CC1 | L3: 0.1 | M3: 25 | N3: 12 | O3: c3ccc(c2ccc1ccccc1c2)cc3 | P3: =VLOOKUP(A3,all_NiCOlit!A:B,2,TRUE) -> https://doi.org/10.1002/chem.201603436 | Q3: 62
A4: 2 | B4: COc1ccc2ccccc2c1 | C4: 1 | D4: [Li]c1ccccc1 | E4: 1.5 | F4: C1CC=CCCC=C1->[Ni]<-C2=CCCC=CCC2 | G4: 0.05 | H4: c1ccccc1C | I4: blank_cell | J4: 0 | K4: C1CCC(P(CCP(C2CCCCC2)C2CCCCC2)C2CCCCC2)CC1 | L4: 0.1 | M4: 25 | N4: 12 | O4: c3ccc(c2ccc1ccccc1c2)cc3 | P4: =VLOOKUP(A4,all_NiCOlit!A:B,2,TRUE) -> https://doi.org/10.1002/chem.201603436 | Q4: 0
A5: 3 | B5: COc1ccc2ccccc2c1 | C5: 1 | D5: [Li]c1ccccc1 | E5: 1.5 | F5: C1CC=CCCC=C1->[Ni]<-C2=CCCC=CCC2 | G5: 0.05 | H5: c1ccccc1C | I5: blank_cell | J5: 0 | K5: CC(C)(C)N1[C]N(C(C)(C)C)C=C1 | L5: 0.1 | M5: 25 | N5: 12 | O5: c3ccc(c2ccc1ccccc1c2)cc3 | P5: =VLOOKUP(A5,all_NiCOlit!A:B,2,TRUE) -> https://doi.org/10.1002/chem.201603436 | Q5: 76
A6: 4 | B6: COc1ccc2ccccc2c1 | C6: 1 | D6: [Li]c1ccccc1 | E6: 1.5 | F6: C1CC=CCCC=C1->[Ni]<-C2=CCCC=CCC2 | G6: 0.05 | H6: c1ccccc1C | I6: blank_cell | J6: 0 | K6: [C]1N(C2CCCCC2)C=CN1C1CCCCC1 | L6: 0.1 | M6: 25 | N6: 12 | O6: c3ccc(c2ccc1ccccc1c2)cc3 | P6: =VLOOKUP(A6,all_NiCOlit!A:B,2,TRUE) -> https://doi.org/10.1002/chem.201603436 | Q6: 66
A7: 5 | B7: COc1ccc2ccccc2c1 | C7: 1 | D7: [Li]c1ccccc1 | E7: 1.5 | F7: C1CC=CCCC=C1->[Ni]<-C2=CCCC=CCC2 | G7: 0.05 | H7: c1ccccc1C | I7: blank_cell | J7: 0 | K7: CC(C)c1cccc(C(C)C)c1N1[C]N(c2c(C(C)C)cccc2C(C)C)C=C1 | L7: 0.1 | M7: 25 | N7: 12 | O7: c3ccc(c2ccc1ccccc1c2)cc3 | P7: =VLOOKUP(A7,all_NiCOlit!A:B,2,TRUE) -> https://doi.org/10.1002/chem.201603436 | Q7: 72
A8: 6 | B8: COc1ccc2ccccc2c1 | C8: 1 | D8: [Li]c1ccccc1 | E8: 1.5 | F8: C1CC=CCCC=C1->[Ni]<-C2=CCCC=CCC2 | G8: 0.05 | H8: c1ccccc1C | I8: blank_cell | J8: 0 | K8: Cc1cc(C)c(N2[C]N(c3c(C)cc(C)cc3C)C=C2)c(C)c1 | L8: 0.1 | M8: 25 | N8: 12 | O8: c3ccc(c2ccc1ccccc1c2)cc3 | P8: =VLOOKUP(A8,all_NiCOlit!A:B,2,TRUE) -> https://doi.org/10.1002/chem.201603436 | Q8: 72
A9: 7 | B9: COc1ccc2ccccc2c1 | C9: 1 | D9: [Li]c1ccccc1 | E9: 1.5 | F9: C1CC=CCCC=C1->[Ni]<-C2=CCCC=CCC2 | G9: 0.05 | H9: c1ccccc1C | I9: blank_cell | J9: 0 | K9: CC(C)c1cccc(C(C)C)c1N1[C]N(c2c(C(C)C)cccc2C(C)C)CC1 | L9: 0.1 | M9: 25 | N9: 12 | O9: c3ccc(c2ccc1ccccc1c2)cc3 | P9: =VLOOKUP(A9,all_NiCOlit!A:B,2,TRUE) -> https://doi.org/10.1002/chem.201603436 | Q9: 71
A10: 8 | B10: COc1ccc2ccccc2c1 | C10: 1 | D10: [Li]c1ccccc1 | E10: 1.5 | F10: C1CC=CCCC=C1->[Ni]<-C2=CCCC=CCC2 | G10: 0.05 | H10: c1ccccc1C | I10: blank_cell | J10: 0 | K10: Cc1cc(C)c(N2[C]N(c3c(C)cc(C)cc3C)CC2)c(C)c1 | L10: 0.1 | M10: 25 | N10: 12 | O10: c3ccc(c2ccc1ccccc1c2)cc3 | P10: =VLOOKUP(A10,all_NiCOlit!A:B,2,TRUE) -> https://doi.org/10.1002/chem.201603436 | Q10: 86
A11: 9 | B11: COc1ccc2ccccc2c1 | C11: 1 | D11: [Li]c1ccccc1 | E11: 1.5 | F11: C1CC=CCCC=C1->[Ni]<-C2=CCCC=CCC2 | G11: 0.05 | H11: CCOCC | I11: blank_cell | J11: 0 | K11: Cc1cc(C)c(N2[C]N(c3c(C)cc(C)cc3C)CC2)c(C)c1 | L11: 0.1 | M11: 25 | N11: 12 | O11: c3ccc(c2ccc1ccccc1c2)cc3 | P11: =VLOOKUP(A11,all_NiCOlit!A:B,2,TRUE) -> https://doi.org/10.1002/chem.201603436 | Q11: 70
A12: 10 | B12: COc1ccc2ccccc2c1 | C12: 1 | D12: [Li]c1ccccc1 | E12: 1.5 | F12: C1CC=CCCC=C1->[Ni]<-C2=CCCC=CCC2 | G12: 0.05 | H12: C1OCCC1 | I12: blank_cell | J12: 0 | K12: Cc1cc(C)c(N2[C]N(c3c(C)cc(C)cc3C)CC2)c(C)c1 | L12: 0.1 | M12: 25 | N12: 12 | O12: c3ccc(c2ccc1ccccc1c2)cc3 | P12: =VLOOKUP(A12,all_NiCOlit!A:B,2,TRUE) -> https://doi.org/10.1002/chem.201603436 | Q12: 6
A13: 11 | B13: COc1ccc2ccccc2c1 | C13: 1 | D13: [Li]c1ccccc1 | E13: 1.5 | F13: C1CC=CCCC=C1->[Ni]<-C2=CCCC=CCC2 | G13: 0.02 | H13: c1ccccc1C | I13: blank_cell | J13: 0 | K13: Cc1cc(C)c(N2[C]N(c3c(C)cc(C)cc3C)CC2)c(C)c1 | L13: 0.04 | M13: 25 | N13: 12 | O13: c3ccc(c2ccc1ccccc1c2)cc3 | P13: =VLOOKUP(A13,all_NiCOlit!A:B,2,TRUE) -> https://doi.org/10.1002/chem.201603436 | Q13: 69
... A1805: 2002 | B1805: COc2ccc1ccccc1c2 | C1805: 1 | D1805: CCCCB1OCC(C)(C)CO1 | E1805: 1.5 | F1805: C1CC=CCCC=C1->[Ni]<-C2=CCCC=CCC2 | G1805: 0.1 | H1805: c1ccccc1C | I1805: CC(C)(C)[O-].[Al+3].[O-]C(C)(C)C.[O-]C(C)(C)C | J1805: 0.2 | K1805: C1CCC(P(C2CCCCC2)C2CCCCC2)CC1 | L1805: 0.4 | M1805: 120 | N1805: 3 | O1805: CCCCc2ccc1ccccc1c2 | P1805: =VLOOKUP(A1805,all_NiCOlit!A:B,2,TRUE) -> Thèse | Q1805: 0

Sheet all_NiCOlit
A1: index | B1: DOI | C1: substrate | D1: coupling_partner | E1: effective_coupling_partner | F1: solvent | G1: time | H1: temperature | I1: catalyst_precursor | J1: reagents | K1: effective_reagents | L1: effective_reagents_covalent | M1: reductant | N1: ligand | O1: effective_ligand | P1: product | Q1: analytical_yield | R1: isolated_yield | S1: coupling_partner_class | T1: origin | U1: eq_substrate | V1: eq_coupling_partner | W1: eq_catalyst | X1: eq_ligand | Y1: eq_reagent | Z1: 2_steps | AA1: scheme_table | AB1: review | AC1: Mechanism
A2: 0 | B2: https://doi.org/10.1002/chem.201603436 | C2: COc1ccc2ccccc2c1 | D2: [Li]c1ccccc1 | E2: [Li]c1ccccc1 | F2: toluene | G2: 12h | H2: rt | I2: Ni(cod)2 | P2: c3ccc(c2ccc1ccccc1c2)cc3 | Q2: 73 | S2: Li | T2: Optimisation | U2: 1 | V2: 1.5 | W2: 0.05 | X2: 0 | Y2: 0 | AA2: Table 1 | AB2: Research_Article | AC2: Murahashi
A3: 1 | B3: https://doi.org/10.1002/chem.201603436 | C3: COc1ccc2ccccc2c1 | D3: [Li]c1ccccc1 | E3: [Li]c1ccccc1 | F3: toluene | G3: 12h | H3: rt | I3: Ni(cod)2 | N3: PCy3 | O3: PCy3 | P3: c3ccc(c2ccc1ccccc1c2)cc3 | Q3: 62 | S3: Li | T3: Optimisation | U3: 1 | V3: 1.5 | W3: 0.05 | X3: 0.1 | Y3: 0 | AA3: Table 1 | AB3: Research_Article | AC3: Murahashi
A4: 2 | B4: https://doi.org/10.1002/chem.201603436 | C4: COc1ccc2ccccc2c1 | D4: [Li]c1ccccc1 | E4: [Li]c1ccccc1 | F4: toluene | G4: 12h | H4: rt | I4: Ni(cod)2 | N4: dcype | O4: dcype | P4: c3ccc(c2ccc1ccccc1c2)cc3 | Q4: 0 | S4: Li | T4: Optimisation | U4: 1 | V4: 1.5 | W4: 0.05 | X4: 0.1 | Y4: 0 | AA4: Table 1 | AB4: Research_Article | AC4: Murahashi
A5: 3 | B5: https://doi.org/10.1002/chem.201603436 | C5: COc1ccc2ccccc2c1 | D5: [Li]c1ccccc1 | E5: [Li]c1ccccc1 | F5: toluene | G5: 12h | H5: rt | I5: Ni(cod)2 | N5: ItBu·HBF4 | O5: ItBu | P5: c3ccc(c2ccc1ccccc1c2)cc3 | Q5: 76 | S5: Li | T5: Optimisation | U5: 1 | V5: 1.5 | W5: 0.05 | X5: 0.1 | Y5: 0 | AA5: Table 1 | AB5: Research_Article | AC5: Murahashi
A6: 4 | B6: https://doi.org/10.1002/chem.201603436 | C6: COc1ccc2ccccc2c1 | D6: [Li]c1ccccc1 | E6: [Li]c1ccccc1 | F6: toluene | G6: 12h | H6: rt | I6: Ni(cod)2 | N6: ICy-HCl | O6: ICy | P6: c3ccc(c2ccc1ccccc1c2)cc3 | Q6: 66 | S6: Li | T6: Optimisation | U6: 1 | V6: 1.5 | W6: 0.05 | X6: 0.1 | Y6: 0 | AA6: Table 1 | AB6: Research_Article | AC6: Murahashi
A7: 5 | B7: https://doi.org/10.1002/chem.201603436 | C7: COc1ccc2ccccc2c1 | D7: [Li]c1ccccc1 | E7: [Li]c1ccccc1 | F7: toluene | G7: 12h | H7: rt | I7: Ni(cod)2 | N7: IPr-HCl | O7: IPr | P7: c3ccc(c2ccc1ccccc1c2)cc3 | Q7: 72 | S7: Li | T7: Optimisation | U7: 1 | V7: 1.5 | W7: 0.05 | X7: 0.1 | Y7: 0 | AA7: Table 1 | AB7: Research_Article | AC7: Murahashi
A8: 6 | B8: https://doi.org/10.1002/chem.201603436 | C8: COc1ccc2ccccc2c1 | D8: [Li]c1ccccc1 | E8: [Li]c1ccccc1 | F8: toluene | G8: 12h | H8: rt | I8: Ni(cod)2 | N8: IMes.HCl | O8: IMes | P8: c3ccc(c2ccc1ccccc1c2)cc3 | Q8: 72 | S8: Li | T8: Optimisation | U8: 1 | V8: 1.5 | W8: 0.05 | X8: 0.1 | Y8: 0 | AA8: Table 1 | AB8: Research_Article | AC8: Murahashi
A9: 7 | B9: https://doi.org/10.1002/chem.201603436 | C9: COc1ccc2ccccc2c1 | D9: [Li]c1ccccc1 | E9: [Li]c1ccccc1 | F9: toluene | G9: 12h | H9: rt | I9: Ni(cod)2 | N9: SIPr-HCl | O9: SIPr | P9: c3ccc(c2ccc1ccccc1c2)cc3 | Q9: 71 | S9: Li | T9: Optimisation | U9: 1 | V9: 1.5 | W9: 0.05 | X9: 0.1 | Y9: 0 | AA9: Table 1 | AB9: Research_Article | AC9: Murahashi
A10: 8 | B10: https://doi.org/10.1002/chem.201603436 | C10: COc1ccc2ccccc2c1 | D10: [Li]c1ccccc1 | E10: [Li]c1ccccc1 | F10: toluene | G10: 12h | H10: rt | I10: Ni(cod)2 | N10: SIMes·HCl | O10: SIMes | P10: c3ccc(c2ccc1ccccc1c2)cc3 | Q10: 86 | S10: Li | T10: Optimisation | U10: 1 | V10: 1.5 | W10: 0.05 | X10: 0.1 | Y10: 0 | AA10: Table 1 | AB10: Research_Article | AC10: Murahashi
A11: 9 | B11: https://doi.org/10.1002/chem.201603436 | C11: COc1ccc2ccccc2c1 | D11: [Li]c1ccccc1 | E11: [Li]c1ccccc1 | F11: Et2O | G11: 12h | H11: rt | I11: Ni(cod)2 | N11: SIMes·HCl | O11: SIMes | P11: c3ccc(c2ccc1ccccc1c2)cc3 | Q11: 70 | S11: Li | T11: Optimisation | U11: 1 | V11: 1.5 | W11: 0.05 | X11: 0.1 | Y11: 0 | AA11: Table 1 | AB11: Research_Article | AC11: Murahashi
A12: 10 | B12: https://doi.org/10.1002/chem.201603436 | C12: COc1ccc2ccccc2c1 | D12: [Li]c1ccccc1 | E12: [Li]c1ccccc1 | F12: THF | G12: 12h | H12: rt | I12: Ni(cod)2 | N12: SIMes·HCl | O12: SIMes | P12: c3ccc(c2ccc1ccccc1c2)cc3 | Q12: 6 | S12: Li | T12: Optimisation | U12: 1 | V12: 1.5 | W12: 0.05 | X12: 0.1 | Y12: 0 | AA12: Table 1 | AB12: Research_Article | AC12: Murahashi
A13: 11 | B13: https://doi.org/10.1002/chem.201603436 | C13: COc1ccc2ccccc2c1 | D13: [Li]c1ccccc1 | E13: [Li]c1ccccc1 | F13: toluene | G13: 12h | H13: rt | I13: Ni(cod)2 | N13: SIMes·HCl | O13: SIMes | P13: c3ccc(c2ccc1ccccc1c2)cc3 | Q13: 69 | S13: Li | T13: Optimisation | U13: 1 | V13: 1.5 | W13: 0.02 | X13: 0.04 | Y13: 0 | AA13: Table 2 | AB13: Research_Article | AC13: Murahashi
A14: 12 | B14: https://doi.org/10.1002/chem.201603436 | C14: COc1ccc2ccccc2c1 | D14: [Li]c1ccccc1 | E14: [Li]c1ccccc1 | F14: toluene | G14: 12h | H14: rt | I14: Ni(cod)2 | N14: SIMes·HCl | O14: SIMes | P14: c3ccc(c2ccc1ccccc1c2)cc3 | Q14: 86 | S14: Li | T14: Optimisation | U14: 1 | V14: 1.5 | W14: 0.05 | X14: 0.01 | Y14: 0 | AA14: Table 2 | AB14: Research_Article | AC14: Murahashi
... A18: 16 | B18: https://doi.org/10.1002/chem.201603436 | C18: COc1ccc2ccccc2c1 | D18: [Li]c1ccccc1 | E18: [Li]c1ccccc1 | F18: toluene | G18: 12h | H18: rt | I18: Ni(cod)2 | N18: SIMes·HCl | O18: SIMes | P18: c3ccc(c2ccc1ccccc1c2)cc3 | Q18: 93 | S18: Li | T18: Optimisation | U18: 1 | V18: 1.5 | W18: 0.1 | X18: 0.2 | Y18: 0 | AA18: Table 2 | AB18: Research_Article | AC18: Murahashi
A19: 17 | B19: https://doi.org/10.1002/chem.201603436 | C19: COc1ccc2ccccc2c1 | D19: [Li]c1ccccc1 | E19: [Li]c1ccccc1 | F19: toluene | G19: 12h | H19: rt | I19: Ni(cod)2 | N19: SIMes·HCl | O19: SIMes | P19: c3ccc(c2ccc1ccccc1c2)cc3 | R19: 92 | S19: Li | T19: Scope | U19: 1 | V19: 1.5 | W19: 0.1 | X19: 0.1 | Y19: 0 | AA19: Scheme 1 | AB19: Research_Article | AC19: Murahashi
A20: 18 | B20: https://doi.org/10.1002/chem.201603436 | C20: COc1ccc2ccccc2c1 | D20: Cc1ccccc1[Li] | E20: Cc1ccccc1[Li] | F20: toluene | G20: 12h | H20: rt | I20: Ni(cod)2 | N20: SIMes·HCl | O20: SIMes | P20: Cc1ccccc1c3ccc2ccccc2c3 | R20: 94 | S20: Li | T20: Scope | U20: 1 | V20: 1.5 | W20: 0.1 | X20: 0.1 | Y20: 0 | AA20: Scheme 1 | AB20: Research_Article | AC20: Murahashi
A21: 19 | B21: https://doi.org/10.1002/chem.201603436 | C21: COc1ccc2ccccc2c1 | D21: Cc1cc(C)c([Li])c(C)c1 | E21: Cc1cc(C)c([Li])c(C)c1 | F21: toluene | G21: 12h | H21: rt | I21: Ni(cod)2 | N21: SIMes·HCl | O21: SIMes | P21: Cc3cc(C)c(c2ccc1ccccc1c2)c(C)c3 | R21: 72 | S21: Li | T21: Scope | U21: 1 | V21: 1.5 | W21: 0.1 | X21: 0.1 | Y21: 0 | AA21: Scheme 1 | AB21: Research_Article | AC21: Murahashi
A22: 20 | B22: https://doi.org/10.1002/chem.201603436 | C22: COc1ccc2ccccc2c1 | D22: CC(C)(C)c1ccc([Li])cc1 | E22: CC(C)(C)c1ccc([Li])cc1 | F22: toluene | G22: 12h | H22: 70°C | I22: Ni(cod)2 | N22: SIMes·HCl | O22: SIMes | P22: CC(C)(C)c3ccc(c2ccc1ccccc1c2)cc3 | R22: 95 | S22: Li | T22: Scope | U22: 1 | V22: 1.5 | W22: 0.1 | X22: 0.1 | Y22: 0 | AA22: Scheme 1 | AB22: Research_Article | AC22: Murahashi
A23: 21 | B23: https://doi.org/10.1002/chem.201603436 | C23: COc1ccc2ccccc2c1 | D23: COc1ccc([Li])cc1 | E23: COc1ccc([Li])cc1 | F23: toluene | G23: 12h | H23: rt | I23: Ni(cod)2 | N23: SIMes·HCl | O23: SIMes | P23: COc3ccc(c2ccc1ccccc1c2)cc3 | R23: 92 | S23: Li | T23: Scope | U23: 1 | V23: 1.5 | W23: 0.1 | X23: 0.1 | Y23: 0 | AA23: Scheme 1 | AB23: Research_Article | AC23: Murahashi
A24: 22 | B24: https://doi.org/10.1002/chem.201603436 | C24: COc1ccc2ccccc2c1 | D24: CC(C)(C)[Si](C)(C)Oc1ccc([Li])cc1 | E24: CC(C)(C)[Si](C)(C)Oc1ccc([Li])cc1 | F24: toluene | G24: 12h | H24: rt | I24: Ni(cod)2 | N24: SIMes·HCl | O24: SIMes | P24: CC(C)(C)[Si](C)(C)Oc3ccc(c2ccc1ccccc1c2)cc3 | R24: 88 | S24: Li | T24: Scope | U24: 1 | V24: 1.5 | W24: 0.1 | X24: 0.1 | Y24: 0 | AA24: Scheme 1 | AB24: Research_Article | AC24: Murahashi
A25: 23 | B25: https://doi.org/10.1002/chem.201603436 | C25: COc1ccc2ccccc2c1 | D25: COCOc1ccccc1[Li] | E25: COCOc1ccccc1[Li] | F25: toluene | G25: 12h | H25: rt | I25: Ni(cod)2 | N25: SIMes·HCl | O25: SIMes | P25: COCOc1ccccc1c3ccc2ccccc2c3 | R25: 84 | S25: Li | T25: Scope | U25: 1 | V25: 1.5 | W25: 0.1 | X25: 0.1 | Y25: 0 | AA25: Scheme 1 | AB25: Research_Article | AC25: Murahashi
A26: 24 | B26: https://doi.org/10.1002/chem.201603436 | C26: COc1ccc2ccccc2c1 | D26: CN(C)c3ccc([Li])cc3 | E26: CN(C)c3ccc([Li])cc3 | F26: toluene | G26: 12h | H26: rt | I26: Ni(cod)2 | N26: SIMes·HCl | O26: SIMes | P26: CN(C)c3ccc(c2ccc1ccccc1c2)cc3 | R26: 90 | S26: Li | T26: Scope | U26: 1 | V26: 1.5 | W26: 0.1 | X26: 0.1 | Y26: 0 | AA26: Scheme 1 | AB26: Research_Article | AC26: Murahashi
A27: 25 | B27: https://doi.org/10.1002/chem.201603436 | C27: COc1ccc2ccccc2c1 | D27: [Li]c1cccc2ccccc12 | E27: [Li]c1cccc2ccccc12 | F27: toluene | G27: 12h | H27: rt | I27: Ni(cod)2 | N27: SIMes·HCl | O27: SIMes | P27: c4ccc3cc(c1cccc2ccccc12)ccc3c4 | R27: 94 | S27: Li | T27: Scope | U27: 1 | V27: 1.5 | W27: 0.1 | X27: 0.1 | Y27: 0 | AA27: Scheme 1 | AB27: Research_Article | AC27: Murahashi
A28: 26 | B28: https://doi.org/10.1002/chem.201603436 | C28: COc1ccc2ccccc2c1 | D28: C[Si](C)(C)Oc3ccc([Li])cc3 | E28: C[Si](C)(C)Oc3ccc([Li])cc3 | F28: toluene | G28: 12h | H28: rt | I28: Ni(cod)2 | N28: SIMes·HCl | O28: SIMes | P28: C[Si](C)(C)Oc3ccc(c2ccc1ccccc1c2)cc3 | R28: 73 | S28: Li | T28: Scope | U28: 1 | V28: 1.5 | W28: 0.1 | X28: 0.1 | Y28: 0 | AA28: Scheme 1 | AB28: Research_Article | AC28: Murahashi
A29: 27 | B29: https://doi.org/10.1002/chem.201603436 | C29: COc1ccc2ccccc2c1 | D29: CC(C)(C)[Si](C)(C)Oc3cccc([Li])c3 | E29: CC(C)(C)[Si](C)(C)Oc3cccc([Li])c3 | F29: toluene | G29: 12h | H29: rt | I29: Ni(cod)2 | N29: SIMes·HCl | O29: SIMes | P29: CC(C)(C)[Si](C)(C)Oc3cccc(c2ccc1ccccc1c2)c3 | R29: 72 | S29: Li | T29: Scope | U29: 1 | V29: 1.5 | W29: 0.1 | X29: 0.1 | Y29: 0 | AA29: Scheme 1 | AB29: Research_Article | AC29: Murahashi
A30: 28 | B30: https://doi.org/10.1002/chem.201603436 | C30: COc1ccc2ccccc2c1 | D30: Cn1cccc1[Li] | E30: Cn1cccc1[Li] | F30: toluene | G30: 12h | H30: 70°C | I30: Ni(cod)2 | N30: SIMes·HCl | O30: SIMes | P30: Cn1cccc1c3ccc2ccccc2c3 | R30: 73 | S30: Li | T30: Scope | U30: 1 | V30: 1.5 | W30: 0.1 | X30: 0.1 | Y30: 0 | AA30: Scheme 1 | AB30: Research_Article | AC30: Murahashi
... A39: 37 | B39: https://doi.org/10.1002/chem.201603436 | C39: COc3ccc2cc(N1CCCCC1)ccc2c3 | D39: [Li]c1ccccc1 | E39: [Li]c1ccccc1 | F39: toluene | G39: 12h | H39: rt | I39: Ni(cod)2 | N39: SIMes | O39: SIMes | P39: c4ccc(c3ccc2cc(N1CCCCC1)ccc2c3)cc4 | R39: 72 | S39: Li | T39: Scope | U39: 1 | V39: 1.5 | W39: 0.1 | X39: 0.1 | Y39: 0 | AA39: Scheme 3 | AB39: Research_Article | AC39: Murahashi
A40: 38 | B40: https://doi.org/10.1002/chem.201603436 | C40: Oc2ccc1ccc(OC)cc1c2 | D40: [Li]c1ccccc1 | E40: [Li]c1ccccc1 | F40: toluene | G40: 12h | H40: rt | I40: Ni(cod)2 | J40: C[Li] | K40: C[Li] | N40: SIMes | O40: SIMes | P40: Oc3ccc2ccc(c1ccccc1)cc2c3 | R40: 89 | S40: Li | T40: Scope | U40: 1 | V40: 1.5 | W40: 0.1 | X40: 0.1 | Y40: 1 | AA40: Scheme 3 | AB40: Research_Article | AC40: Murahashi
A41: 39 | B41: https://doi.org/10.1002/chem.201603436 | C41: c2ccc1cccc(OC)c1c2 | D41: COc1ccc([Li])cc1 | E41: COc1ccc([Li])cc1 | F41: toluene | G41: 12h | H41: 50°C | I41: Ni(cod)2 | N41: SIMes | O41: SIMes | P41: COc3ccc(c1cccc2ccccc12)cc3 | R41: 90 | S41: Li | T41: Scope | U41: 1 | V41: 1.5 | W41: 0.1 | X41: 0.1 | Y41: 0 | AA41: Scheme 3 | AB41: Research_Article | AC41: Murahashi
A42: 40 | B42: https://doi.org/10.1002/chem.201603436 | C42: COc2ccc1ccc(OC)cc1c2 | D42: Cc1ccccc1[Li] | E42: Cc1ccccc1[Li] | F42: toluene | G42: 12h | H42: rt | I42: Ni(cod)2 | N42: SIMes | O42: SIMes | P42: Cc1ccccc1c4ccc3ccc(c2c(C)cccc2)cc3c4 | R42: 85 | S42: Li | T42: Scope | U42: 1 | V42: 1.5 | W42: 0.1 | X42: 0.1 | Y42: 0 | Z42: Yes | AA42: Scheme 3 | AB42: Research_Article | AC42: Murahashi
A43: 41 | B43: https://doi.org/10.1002/chem.201603436 | C43: COc1ccc(C)cc1 | D43: CN(C)c3ccc([Li])cc3 | E43: CN(C)c3ccc([Li])cc3 | F43: toluene | G43: 12h | H43: 90°C | I43: Ni(cod)2 | N43: SIMes | O43: SIMes | P43: Cc2ccc(c1ccc(N(C)C)cc1)cc2 | R43: 30 | S43: Li | T43: Scope | U43: 1 | V43: 1.5 | W43: 0.1 | X43: 0.1 | Y43: 0 | AA43: Scheme 3 | AB43: Research_Article | AC43: Murahashi
A44: 42 | B44: https://doi.org/10.1002/chem.201603436 | C44: COc1ccc([C@@H](C)N(C)C)cc1 | D44: Cc1ccccc1[Li] | E44: Cc1ccccc1[Li] | F44: toluene | G44: 12h | H44: 70°C | I44: Ni(cod)2 | N44: SIMes | O44: SIMes | P44: Cc1ccccc1c2ccc([C@@H](C)N(C)C)cc2 | R44: 86 | S44: Li | T44: Scope | U44: 1 | V44: 1.5 | W44: 0.1 | X44: 0.1 | Y44: 0 | AA44: Scheme 3 | AB44: Research_Article | AC44: Murahashi
A45: 43 | B45: https://doi.org/10.1002/chem.201603436 | C45: COc1ccc([C@H](C)N(C)C)cc1 | D45: Cc1ccccc1[Li] | E45: Cc1ccccc1[Li] | F45: toluene | G45: 12h | H45: 70°C | I45: Ni(cod)2 | N45: SIMes | O45: SIMes | P45: Cc1ccccc1c2ccc([C@H](C)N(C)C)cc2 | R45: 88 | S45: Li | T45: Scope | U45: 1 | V45: 1.5 | W45: 0.1 | X45: 0.1 | Y45: 0 | AA45: Scheme 3 | AB45: Research_Article | AC45: Murahashi
A46: 44 | B46: https://doi.org/10.1002/chem.201603436 | C46: COc1ccc(CO)cc1 | D46: Cc1ccccc1[Li] | E46: Cc1ccccc1[Li] | F46: toluene | G46: 12h | H46: 50°C | I46: Ni(cod)2 | J46: C[Li] | K46: C[Li] | N46: SIMes | O46: SIMes | P46: Cc1ccccc1c2ccc(CO)cc2 | R46: 85 | S46: Li | T46: Scope | U46: 1 | V46: 1.5 | W46: 0.1 | X46: 0.1 | Y46: 1 | AA46: Scheme 3 | AB46: Research_Article | AC46: Murahashi
A47: 45 | B47: https://doi.org/10.1002/chem.201603436 | C47: COc1ccc(CCO)cc1 | D47: Cc1ccccc1[Li] | E47: Cc1ccccc1[Li] | F47: toluene | G47: 12h | H47: 50°C | I47: Ni(cod)2 | J47: C[Li] | K47: C[Li] | N47: SIMes | O47: SIMes | P47: Cc1ccccc1c2ccc(CCO)cc2 | R47: 86 | S47: Li | T47: Scope | U47: 1 | V47: 1.5 | W47: 0.1 | X47: 0.1 | Y47: 1 | AA47: Scheme 3 | AB47: Research_Article | AC47: Murahashi
A48: 46 | B48: https://doi.org/10.1002/chem.201603436 | C48: COc2ccc1ncccc1c2 | D48: CN(C)c1ccc([Li])cc1 | E48: CN(C)c1ccc([Li])cc1 | F48: toluene | G48: 12h | H48: 50°C | I48: Ni(cod)2 | N48: SIMes | O48: SIMes | P48: CN(C)c3ccc(c2ccc1ncccc1c2)cc3 | R48: 51 | S48: Li | T48: Scope | U48: 1 | V48: 1.5 | W48: 0.1 | X48: 0.1 | Y48: 0 | AA48: Scheme 3 | AB48: Research_Article | AC48: Murahashi
A49: 47 | B49: https://doi.org/10.1002/chem.201603436 | C49: COc2ccc1c(ccn1C)c2 | D49: Cc1ccccc1[Li] | E49: Cc1ccccc1[Li] | F49: toluene | G49: 12h | H49: 90°C | I49: Ni(cod)2 | N49: SIMes | O49: SIMes | P49: Cc1ccccc1c3ccc2c(ccn2C)c3 | R49: 40 | S49: Li | T49: Scope | U49: 1 | V49: 1.5 | W49: 0.1 | X49: 0.1 | Y49: 0 | AA49: Scheme 3 | AB49: Research_Article | AC49: Murahashi
A50: 48 | B50: https://doi.org/10.1002/chem.201603436 | C50: COc1ccc3c(c1)c2ccccc2n3C | D50: Cc1ccccc1[Li] | E50: Cc1ccccc1[Li] | F50: toluene | G50: 12h | H50: 90°C | I50: Ni(cod)2 | N50: SIMes | O50: SIMes | P50: Cc1ccccc1c2ccc4c(c2)c3ccccc3n4C | R50: 41 | S50: Li | T50: Scope | U50: 1 | V50: 1.5 | W50: 0.1 | X50: 0.1 | Y50: 0 | AA50: Scheme 3 | AB50: Research_Article | AC50: Murahashi
A51: 49 | B51: https://doi.org/10.1002/chem.201603436 | C51: CCOc2ccc1ccccc1c2 | D51: [Li]c1ccccc1 | E51: [Li]c1ccccc1 | F51: toluene | G51: 12h | H51: rt | I51: Ni(cod)2 | N51: SIMes | O51: SIMes | P51: c3ccc(c2ccc1ccccc1c2)cc3 | Q51: 78 | S51: Li | T51: Scope | U51: 1 | V51: 1.5 | W51: 0.1 | X51: 0.1 | Y51: 0 | AA51: Scheme 4 | AB51: Research_Article | AC51: Murahashi
...
